Workbook

Sheet Issue Register
A1: PitchDeck - Code Review Issue Register
A2: Repo: github.com/NikhileshU/PitchDeck | 6 review rounds, 43062a6 -> da764c2 (phase-6-report) | Updated 12 Aug 2026. Severity and status as assessed by the reviewer.
A4: ID | B4: Round | C4: Commit reviewed | D4: File | E4: Location | F4: Severity | G4: Category | H4: Issue | I4: Status | J4: Closed in
A5: R1-C1 | B5: 1 | C5: 43062a6 | D5: render_html.py | E5: _chart_bar / _vmax (114-117) | F5: Critical | G5: Correctness | H5: Negative bar values silently dropped. Probe values=[-5,10] emitted 1 path, expected 2. | I5: Fixed | J5: 4abca60
A6: R1-C2 | B6: 1 | C6: 43062a6 | D6: render_html.py | E6: _chart_line (154-165) | F6: Critical | G6: Correctness | H6: Single negative line point plotted off-canvas: cy=569.6 in a viewBox of height 320. | I6: Fixed | J6: 4abca60
A7: R1-C3 | B7: 1 | C7: 43062a6 | D7: themes/base.css | E7: .card (~48) | F7: Critical | G7: Correctness | H7: overflow:hidden clips, contradicting card-schema.md section 5 'do not clip'; no type ramp implemented. | I7: Fixed | J7: 4abca60
A8: R1-C4 | B8: 1 | C8: 43062a6 | D8: export_pdf.py | E8: export (52) | F8: Critical | G8: Correctness | H8: Stale-PDF false pass: output never unlinked, so a previous run's PDF satisfies both the size and %PDF- checks. | I8: Fixed | J8: 4abca60
A9: R1-H5 | B9: 1 | C9: 43062a6 | D9: render_html.py | E9: main (343-344) | F9: High | G9: Correctness | H9: Missing base.css fails open - renders an unstyled deck and exits 0. | I9: Fixed | J9: 4abca60
A10: R1-H6 | B10: 1 | C10: 43062a6 | D10: render_html.py | E10: _resolve_images (325-331) | F10: High | G10: Correctness | H10: 'Self-contained HTML' claim false: src rewritten to absolute local paths, breaks off-machine. | I10: Fixed | J10: 4abca60
A11: R1-S1 | B11: 1 | C11: 43062a6 | D11: render_html.py | E11: _chart_svg (101,105) | F11: Suggestion | G11: Correctness | H11: Bare tracebacks on bad IR: ZeroDivisionError on empty values, KeyError on unknown block/chart type. | I11: Fixed | J11: 4abca60
A12: R1-S2 | B12: 1 | C12: 43062a6 | D12: render_html.py | E12: _chart_pie (186-188) | F12: Suggestion | G12: Correctness | H12: Pie silently uses series[0] and discards the rest; IndexError on empty series; negatives produce nonsense arcs. | I12: Fixed | J12: 4abca60
A13: R1-S3 | B13: 1 | C13: 43062a6 | D13: render_html.py | E13: _resolve_images (325-331) | F13: Suggestion | G13: Correctness | H13: Mutates the loaded IR in place; corrupting if deck.json is ever re-serialised. | I13: Fixed | J13: 4abca60
A14: R1-S4 | B14: 1 | C14: 43062a6 | D14: render_html.py | E14: _legend / _chart_hbar (69-77,128,144) | F14: Suggestion | G14: Correctness | H14: Text overflow unhandled: legend has no wrap or width cap; long hbar category labels run off the left edge. | I14: Fixed | J14: 8d313de
A15: R1-S5 | B15: 1 | C15: 43062a6 | D15: render_html.py | E15: _chart_hbar (144) | F15: Suggestion | G15: Style | H15: hbar labels every bar unconditionally while bar applies a label_all = m*n <= 8 density guard. | I15: Open
A16: R1-S6 | B16: 1 | C16: 43062a6 | D16: export_pdf.py | E16: export (43-51) | F16: Suggestion | G16: Correctness | H16: No virtual-time budget or compositor flag; find_browser uses .exists() rather than os.access(X_OK). | I16: Fixed | J16: 4abca60
A17: R1-S7 | B17: 1 | C17: 43062a6 | D17: export_pdf.py | E17: export (51-54) | F17: Suggestion | G17: Correctness | H17: Non-zero browser exit surfaced only when the file check fails. | I17: Fixed | J17: 4abca60
A18: R1-S8 | B18: 1 | C18: 43062a6 | D18: render_html.py | E18: _css_vars (37-60) | F18: Suggestion | G18: Security | H18: Theme values interpolated into <style> unescaped; a crafted value could break out of the block. | I18: Fixed | J18: 4abca60
A19: R1-S9 | B19: 1 | C19: 43062a6 | D19: render_html.py | E19: _b_callout / _b_image (261,270) | F19: Suggestion | G19: Correctness | H19: tone and fit become class names unvalidated; an unknown value renders unstyled with no error. | I19: Fixed | J19: 4abca60
A20: R1-S10 | B20: 1 | C20: 43062a6 | D20: CLAUDE.md | E20: invariant 3 | F20: Suggestion | G20: Maintainability | H20: render() signature deviates from the documented 3-arg contract (css kwarg undocumented). | I20: Fixed | J20: 4abca60
A21: R1-S11 | B21: 1 | C21: 43062a6 | D21: evals/ | E21: - | F21: Suggestion | G21: Test coverage | H21: No tests and no golden outputs at phase 4; phases 5, 6 and 9 would be written against unpinned output. | I21: Fixed | J21: 2eb086e
A22: R2-H1 | B22: 2 | C22: 4abca60 | D22: render_html.py | E22: _cssv (~30) | F22: High | G22: Security | H22: Denylist hole: url(http://...) and 'red; --color-text: red' both allowed, enabling a remote fetch during PDF export. | I22: Fixed | J22: 8d313de
A23: R2-H2 | B23: 2 | C23: 4abca60 | D23: .claude/settings.local.json + CLAUDE.md | E23: whole file | F23: High | G23: Maintainability | H23: Unrelated tooling config committed to a public repo; 84-line dgc-policy block contradicts invariant 10 and leaks local paths. | I23: Fixed | J23: 8d313de
A24: R2-H3 | B24: 2 | C24: 4abca60 | D24: base.css / export_pdf.py | E24: - | F24: High | G24: Correctness | H24: PDF still clips silently: @page fixed at 1280x720px with no cards==pages assertion. | I24: Fixed | J24: 8d313de
A25: R2-S1 | B25: 2 | C25: 4abca60 | D25: render_html.py | E25: _legend | F25: Suggestion | G25: Correctness | H25: _trunc(name,18) reduces but does not bound legend width; no cumulative width clamp, no series cap. | I25: Fixed | J25: 8d313de
A26: R2-S2 | B26: 2 | C26: 4abca60 | D26: render_html.py | E26: _embed_images | F26: Suggestion | G26: Performance | H26: No size guard and no dedup; the same image is base64-encoded once per card. | I26: Fixed | J26: 8d313de
A27: R2-S3 | B27: 2 | C27: 4abca60 | D27: render_html.py | E27: _embed_images | F27: Suggestion | G27: Maintainability | H27: Image resolution diverges for phase 9: python-pptx add_picture needs a path or stream, not a data URI. | I27: Open
A28: R2-S4 | B28: 2 | C28: 4abca60 | D28: render_html.py | E28: _block | F28: Suggestion | G28: Maintainability | H28: Broad except re-labels genuine renderer bugs as IR faults. | I28: Fixed | J28: 8d313de
A29: R2-S5 | B29: 2 | C29: 4abca60 | D29: export_pdf.py | E29: find_browser (~33) | F29: Suggestion | G29: Style | H29: import os nested inside the function while all other imports are top-level. | I29: Fixed | J29: 8d313de
A30: R2-S6 | B30: 2 | C30: 4abca60 | D30: export_pdf.py | E30: export (~44) | F30: Suggestion | G30: Correctness | H30: --virtual-time-budget support is patchy in new headless mode; needed verification on Brave. | I30: Closed - not an issue
A31: R2-S7 | B31: 2 | C31: 4abca60 | D31: .gitignore | E31: - | F31: Suggestion | G31: Style | H31: Missing __pycache__/, .DS_Store and CONTEXT.md entries. | I31: Fixed | J31: 8d313de
A32: R2-S8 | B32: 2 | C32: 4abca60 | D32: render_html.py | E32: - | F32: Suggestion | G32: Maintainability | H32: 393 of 400 lines with chart geometry still to be shared with render_pptx.py; extraction now urgent. | I32: Open
A33: R3-C1 | B33: 3 | C33: 2eb086e | D33: validate.py | E33: _is_claim (202) | F33: Critical | G33: Correctness | H33: title-is-claim wrong in both directions at error severity; noun phrases pass on any lemma token, verb-less claims blocked. | I33: Fixed | J33: 39d155b
A34: R3-H2 | B34: 3 | C34: 2eb086e | D34: validate.py | E34: check_chart_fit (294) | F34: High | G34: Correctness | H34: Fires on standard practice: a four-quarter bar chart warns; _TEMPORAL matches any bare 4-digit string. | I34: Fixed | J34: 8d313de
A35: R3-H3 | B35: 3 | C35: 2eb086e | D35: validate.py | E35: _lum (311) | F35: High | G35: Correctness | H35: Crashes on any non-hex theme colour; renderer permitted named/functional colours, so the two disagreed on a legal theme. | I35: Fixed | J35: 8d313de
A36: R3-H4 | B36: 3 | C36: 2eb086e | D36: validate.py | E36: main (426) | F36: High | G36: Correctness | H36: A PASS did not mean the deck renders: image src existence unchecked, so a missing file died later in _embed_images. | I36: Fixed | J36: 8d313de
A37: R3-S1 | B37: 3 | C37: 2eb086e | D37: validate.py | E37: check_schema (153-160) | F37: Suggestion | G37: Correctness | H37: ids[cid] inserted even when cid is None, producing a spurious 'duplicate id None'. | I37: Fixed | J37: 8d313de
A38: R3-S2 | B38: 3 | C38: 2eb086e | D38: validate.py | E38: main (426-427) | F38: Suggestion | G38: Maintainability | H38: Malformed deck.json produced a raw JSONDecodeError traceback. | I38: Fixed | J38: 8d313de
A39: R3-S3 | B39: 3 | C39: 2eb086e | D39: validate.py | E39: _block_h (343) | F39: Suggestion | G39: Correctness | H39: Overflow estimator constants uncalibrated by measurement while driving an error-severity finding. | I39: Deferred - phase 8
A40: R3-S4 | B40: 3 | C40: 2eb086e | D40: validate.py | E40: check_evidence (260) | F40: Suggestion | G40: Correctness | H40: A divider counted as evidence. | I40: Fixed | J40: 8d313de
A41: R3-S5 | B41: 3 | C41: 2eb086e | D41: validate.py | E41: main (422) | F41: Suggestion | G41: Maintainability | H41: --passes parsed and written into findings.json but consumed by nothing. | I41: Deferred - phase 6
...

Sheet Summary
A1: Summary
A2: Every figure is a COUNTIF over 'Issue Register' - edit that sheet and these update.
A4: By severity
A5: Severity | B5: Count
A6: Critical | B6: =COUNTIF('Issue Register'!$F$5:$F$60,"Critical") -> 6
A7: High | B7: =COUNTIF('Issue Register'!$F$5:$F$60,"High") -> 13
A8: Medium | B8: =COUNTIF('Issue Register'!$F$5:$F$60,"Medium") -> 7
A9: Low | B9: =COUNTIF('Issue Register'!$F$5:$F$60,"Low") -> 2
A10: Suggestion | B10: =COUNTIF('Issue Register'!$F$5:$F$60,"Suggestion") -> 25
A11: Action | B11: =COUNTIF('Issue Register'!$F$5:$F$60,"Action") -> 3
A12: Total | B12: =SUM(B6:B11) -> 56
A14: By status
A15: Status | B15: Count
A16: Fixed | B16: =COUNTIF('Issue Register'!$I$5:$I$60,"Fixed") -> 37
A17: Open | B17: =COUNTIF('Issue Register'!$I$5:$I$60,"Open") -> 16
A18: Deferred - phase 6 | B18: =COUNTIF('Issue Register'!$I$5:$I$60,"Deferred - phase 6") -> 1
A19: Deferred - phase 8 | B19: =COUNTIF('Issue Register'!$I$5:$I$60,"Deferred - phase 8") -> 1
A20: Closed - not an issue | B20: =COUNTIF('Issue Register'!$I$5:$I$60,"Closed - not an issue") -> 1
A21: Total | B21: =SUM(B16:B20) -> 56
A23: By review round
A24: Round | B24: Count
A25: 1 | B25: =COUNTIF('Issue Register'!$B$5:$B$60,1) -> 17
A26: 2 | B26: =COUNTIF('Issue Register'!$B$5:$B$60,2) -> 11
A27: 3 | B27: =COUNTIF('Issue Register'!$B$5:$B$60,3) -> 10
A28: 4 | B28: =COUNTIF('Issue Register'!$B$5:$B$60,4) -> 5
A29: 5 | B29: =COUNTIF('Issue Register'!$B$5:$B$60,5) -> 4
A30: 6 | B30: =COUNTIF('Issue Register'!$B$5:$B$60,6) -> 9
A31: Total | B31: =SUM(B25:B30) -> 56
A33: By category
A34: Category | B34: Count
A35: Correctness | B35: =COUNTIF('Issue Register'!$G$5:$G$60,"Correctness") -> 33
A36: Security | B36: =COUNTIF('Issue Register'!$G$5:$G$60,"Security") -> 2
A37: Performance | B37: =COUNTIF('Issue Register'!$G$5:$G$60,"Performance") -> 1
A38: Maintainability | B38: =COUNTIF('Issue Register'!$G$5:$G$60,"Maintainability") -> 12
A39: Style | B39: =COUNTIF('Issue Register'!$G$5:$G$60,"Style") -> 6
A40: Test coverage | B40: =COUNTIF('Issue Register'!$G$5:$G$60,"Test coverage") -> 2
A41: Total | B41: =SUM(B35:B40) -> 56
A43: Still open
A44: Open items only, by severity (blocking work for phase 6 onward):
A45: Severity | B45: Open count
...
